<?xml version="1.0" encoding="UTF-8"?>
<testsuites>
  <testsuite id="0" name="D:\gitworkspace\angular\wings2\angular-node-teamtracker\nodejs\test\teams.test.js" errors="0" package="D:\gitworkspace\angular\wings2\angular-node-teamtracker\nodejs\test\teams.test.js" hostname="localhost" tests="16" failures="16" time="12.579" timestamp="2024-03-10T17:45:28">
    <properties>
    </properties>
    <testcase classname="Adding a new member" name="Adding a new member" time="0">
      <failure message="Error: expected 201 &quot;Created&quot;, got 404 &quot;Not Found&quot;
    at Test.Object.&lt;anonymous&gt;.Test._assertStatus (D:\gitworkspace\angular\wings2\angular-node-teamtracker\nodejs\node_modules\supertest\lib\test.js:270:12)
    at Test.Object.&lt;anonymous&gt;.Test._assertFunction (D:\gitworkspace\angular\wings2\angular-node-teamtracker\nodejs\node_modules\supertest\lib\test.js:285:11)
    at Test.Object.&lt;anonymous&gt;.Test.assert (D:\gitworkspace\angular\wings2\angular-node-teamtracker\nodejs\node_modules\supertest\lib\test.js:175:21)
    at Server.localAssert (D:\gitworkspace\angular\wings2\angular-node-teamtracker\nodejs\node_modules\supertest\lib\test.js:133:12)
    at Object.onceWrapper (events.js:519:28)
    at Server.emit (events.js:400:28)
    at emitCloseNT (net.js:1677:8)
    at processTicksAndRejections (internal/process/task_queues.js:81:21)" type="AssertionError">
      </failure>
    </testcase>
    <testcase classname="Adding a new member" name="Adding a new member" time="0">
      <failure message="Error: expected 201 &quot;Created&quot;, got 404 &quot;Not Found&quot;
    at Test.Object.&lt;anonymous&gt;.Test._assertStatus (D:\gitworkspace\angular\wings2\angular-node-teamtracker\nodejs\node_modules\supertest\lib\test.js:270:12)
    at Test.Object.&lt;anonymous&gt;.Test._assertFunction (D:\gitworkspace\angular\wings2\angular-node-teamtracker\nodejs\node_modules\supertest\lib\test.js:285:11)
    at Test.Object.&lt;anonymous&gt;.Test.assert (D:\gitworkspace\angular\wings2\angular-node-teamtracker\nodejs\node_modules\supertest\lib\test.js:175:21)
    at Server.localAssert (D:\gitworkspace\angular\wings2\angular-node-teamtracker\nodejs\node_modules\supertest\lib\test.js:133:12)
    at Object.onceWrapper (events.js:519:28)
    at Server.emit (events.js:400:28)
    at emitCloseNT (net.js:1677:8)
    at processTicksAndRejections (internal/process/task_queues.js:81:21)" type="AssertionError">
      </failure>
    </testcase>
    <testcase classname="Adding a new member" name="Adding a new member" time="0">
      <failure message="Error: expected 400 &quot;Bad Request&quot;, got 404 &quot;Not Found&quot;
    at Test.Object.&lt;anonymous&gt;.Test._assertStatus (D:\gitworkspace\angular\wings2\angular-node-teamtracker\nodejs\node_modules\supertest\lib\test.js:270:12)
    at Test.Object.&lt;anonymous&gt;.Test._assertFunction (D:\gitworkspace\angular\wings2\angular-node-teamtracker\nodejs\node_modules\supertest\lib\test.js:285:11)
    at Test.Object.&lt;anonymous&gt;.Test.assert (D:\gitworkspace\angular\wings2\angular-node-teamtracker\nodejs\node_modules\supertest\lib\test.js:175:21)
    at Server.localAssert (D:\gitworkspace\angular\wings2\angular-node-teamtracker\nodejs\node_modules\supertest\lib\test.js:133:12)
    at Object.onceWrapper (events.js:519:28)
    at Server.emit (events.js:400:28)
    at emitCloseNT (net.js:1677:8)
    at processTicksAndRejections (internal/process/task_queues.js:81:21)" type="AssertionError">
      </failure>
    </testcase>
    <testcase classname="Adding a new member with invalid employee name" name="Adding a new member with invalid employee name" time="0">
      <failure message="Error: expected 400 &quot;Bad Request&quot;, got 404 &quot;Not Found&quot;
    at Test.Object.&lt;anonymous&gt;.Test._assertStatus (D:\gitworkspace\angular\wings2\angular-node-teamtracker\nodejs\node_modules\supertest\lib\test.js:270:12)
    at Test.Object.&lt;anonymous&gt;.Test._assertFunction (D:\gitworkspace\angular\wings2\angular-node-teamtracker\nodejs\node_modules\supertest\lib\test.js:285:11)
    at Test.Object.&lt;anonymous&gt;.Test.assert (D:\gitworkspace\angular\wings2\angular-node-teamtracker\nodejs\node_modules\supertest\lib\test.js:175:21)
    at Server.localAssert (D:\gitworkspace\angular\wings2\angular-node-teamtracker\nodejs\node_modules\supertest\lib\test.js:133:12)
    at Object.onceWrapper (events.js:519:28)
    at Server.emit (events.js:400:28)
    at emitCloseNT (net.js:1677:8)
    at processTicksAndRejections (internal/process/task_queues.js:81:21)" type="AssertionError">
      </failure>
    </testcase>
    <testcase classname="Adding a new member with invalid employee name" name="Adding a new member with invalid employee name" time="0">
      <failure message="Error: expected 400 &quot;Bad Request&quot;, got 404 &quot;Not Found&quot;
    at Test.Object.&lt;anonymous&gt;.Test._assertStatus (D:\gitworkspace\angular\wings2\angular-node-teamtracker\nodejs\node_modules\supertest\lib\test.js:270:12)
    at Test.Object.&lt;anonymous&gt;.Test._assertFunction (D:\gitworkspace\angular\wings2\angular-node-teamtracker\nodejs\node_modules\supertest\lib\test.js:285:11)
    at Test.Object.&lt;anonymous&gt;.Test.assert (D:\gitworkspace\angular\wings2\angular-node-teamtracker\nodejs\node_modules\supertest\lib\test.js:175:21)
    at Server.localAssert (D:\gitworkspace\angular\wings2\angular-node-teamtracker\nodejs\node_modules\supertest\lib\test.js:133:12)
    at Object.onceWrapper (events.js:519:28)
    at Server.emit (events.js:400:28)
    at emitCloseNT (net.js:1677:8)
    at processTicksAndRejections (internal/process/task_queues.js:81:21)" type="AssertionError">
      </failure>
    </testcase>
    <testcase classname="Adding a new member with invalid employee name" name="Adding a new member with invalid employee name" time="0">
      <failure message="Error: expected 400 &quot;Bad Request&quot;, got 404 &quot;Not Found&quot;
    at Test.Object.&lt;anonymous&gt;.Test._assertStatus (D:\gitworkspace\angular\wings2\angular-node-teamtracker\nodejs\node_modules\supertest\lib\test.js:270:12)
    at Test.Object.&lt;anonymous&gt;.Test._assertFunction (D:\gitworkspace\angular\wings2\angular-node-teamtracker\nodejs\node_modules\supertest\lib\test.js:285:11)
    at Test.Object.&lt;anonymous&gt;.Test.assert (D:\gitworkspace\angular\wings2\angular-node-teamtracker\nodejs\node_modules\supertest\lib\test.js:175:21)
    at Server.localAssert (D:\gitworkspace\angular\wings2\angular-node-teamtracker\nodejs\node_modules\supertest\lib\test.js:133:12)
    at Object.onceWrapper (events.js:519:28)
    at Server.emit (events.js:400:28)
    at emitCloseNT (net.js:1677:8)
    at processTicksAndRejections (internal/process/task_queues.js:81:21)" type="AssertionError">
      </failure>
    </testcase>
    <testcase classname="Adding a new member with invalid experience" name="Adding a new member with invalid experience" time="0">
      <failure message="Error: expected 400 &quot;Bad Request&quot;, got 404 &quot;Not Found&quot;
    at Test.Object.&lt;anonymous&gt;.Test._assertStatus (D:\gitworkspace\angular\wings2\angular-node-teamtracker\nodejs\node_modules\supertest\lib\test.js:270:12)
    at Test.Object.&lt;anonymous&gt;.Test._assertFunction (D:\gitworkspace\angular\wings2\angular-node-teamtracker\nodejs\node_modules\supertest\lib\test.js:285:11)
    at Test.Object.&lt;anonymous&gt;.Test.assert (D:\gitworkspace\angular\wings2\angular-node-teamtracker\nodejs\node_modules\supertest\lib\test.js:175:21)
    at Server.localAssert (D:\gitworkspace\angular\wings2\angular-node-teamtracker\nodejs\node_modules\supertest\lib\test.js:133:12)
    at Object.onceWrapper (events.js:519:28)
    at Server.emit (events.js:400:28)
    at emitCloseNT (net.js:1677:8)
    at processTicksAndRejections (internal/process/task_queues.js:81:21)" type="AssertionError">
      </failure>
    </testcase>
    <testcase classname="Adding a new member without employee id" name="Adding a new member without employee id" time="0">
      <failure message="Error: expected 400 &quot;Bad Request&quot;, got 404 &quot;Not Found&quot;
    at Test.Object.&lt;anonymous&gt;.Test._assertStatus (D:\gitworkspace\angular\wings2\angular-node-teamtracker\nodejs\node_modules\supertest\lib\test.js:270:12)
    at Test.Object.&lt;anonymous&gt;.Test._assertFunction (D:\gitworkspace\angular\wings2\angular-node-teamtracker\nodejs\node_modules\supertest\lib\test.js:285:11)
    at Test.Object.&lt;anonymous&gt;.Test.assert (D:\gitworkspace\angular\wings2\angular-node-teamtracker\nodejs\node_modules\supertest\lib\test.js:175:21)
    at Server.localAssert (D:\gitworkspace\angular\wings2\angular-node-teamtracker\nodejs\node_modules\supertest\lib\test.js:133:12)
    at Object.onceWrapper (events.js:519:28)
    at Server.emit (events.js:400:28)
    at emitCloseNT (net.js:1677:8)
    at processTicksAndRejections (internal/process/task_queues.js:81:21)" type="AssertionError">
      </failure>
    </testcase>
    <testcase classname="Adding a new member without employee name" name="Adding a new member without employee name" time="0">
      <failure message="Error: expected 400 &quot;Bad Request&quot;, got 404 &quot;Not Found&quot;
    at Test.Object.&lt;anonymous&gt;.Test._assertStatus (D:\gitworkspace\angular\wings2\angular-node-teamtracker\nodejs\node_modules\supertest\lib\test.js:270:12)
    at Test.Object.&lt;anonymous&gt;.Test._assertFunction (D:\gitworkspace\angular\wings2\angular-node-teamtracker\nodejs\node_modules\supertest\lib\test.js:285:11)
    at Test.Object.&lt;anonymous&gt;.Test.assert (D:\gitworkspace\angular\wings2\angular-node-teamtracker\nodejs\node_modules\supertest\lib\test.js:175:21)
    at Server.localAssert (D:\gitworkspace\angular\wings2\angular-node-teamtracker\nodejs\node_modules\supertest\lib\test.js:133:12)
    at Object.onceWrapper (events.js:519:28)
    at Server.emit (events.js:400:28)
    at emitCloseNT (net.js:1677:8)
    at processTicksAndRejections (internal/process/task_queues.js:81:21)" type="AssertionError">
      </failure>
    </testcase>
    <testcase classname="Adding a new member without experience" name="Adding a new member without experience" time="0">
      <failure message="Error: expected 400 &quot;Bad Request&quot;, got 404 &quot;Not Found&quot;
    at Test.Object.&lt;anonymous&gt;.Test._assertStatus (D:\gitworkspace\angular\wings2\angular-node-teamtracker\nodejs\node_modules\supertest\lib\test.js:270:12)
    at Test.Object.&lt;anonymous&gt;.Test._assertFunction (D:\gitworkspace\angular\wings2\angular-node-teamtracker\nodejs\node_modules\supertest\lib\test.js:285:11)
    at Test.Object.&lt;anonymous&gt;.Test.assert (D:\gitworkspace\angular\wings2\angular-node-teamtracker\nodejs\node_modules\supertest\lib\test.js:175:21)
    at Server.localAssert (D:\gitworkspace\angular\wings2\angular-node-teamtracker\nodejs\node_modules\supertest\lib\test.js:133:12)
    at Object.onceWrapper (events.js:519:28)
    at Server.emit (events.js:400:28)
    at emitCloseNT (net.js:1677:8)
    at processTicksAndRejections (internal/process/task_queues.js:81:21)" type="AssertionError">
      </failure>
    </testcase>
    <testcase classname="Adding a new member without technology name" name="Adding a new member without technology name" time="0">
      <failure message="Error: expected 400 &quot;Bad Request&quot;, got 404 &quot;Not Found&quot;
    at Test.Object.&lt;anonymous&gt;.Test._assertStatus (D:\gitworkspace\angular\wings2\angular-node-teamtracker\nodejs\node_modules\supertest\lib\test.js:270:12)
    at Test.Object.&lt;anonymous&gt;.Test._assertFunction (D:\gitworkspace\angular\wings2\angular-node-teamtracker\nodejs\node_modules\supertest\lib\test.js:285:11)
    at Test.Object.&lt;anonymous&gt;.Test.assert (D:\gitworkspace\angular\wings2\angular-node-teamtracker\nodejs\node_modules\supertest\lib\test.js:175:21)
    at Server.localAssert (D:\gitworkspace\angular\wings2\angular-node-teamtracker\nodejs\node_modules\supertest\lib\test.js:133:12)
    at Object.onceWrapper (events.js:519:28)
    at Server.emit (events.js:400:28)
    at emitCloseNT (net.js:1677:8)
    at processTicksAndRejections (internal/process/task_queues.js:81:21)" type="AssertionError">
      </failure>
    </testcase>
    <testcase classname="Getting technologies from DB" name="Getting technologies from DB" time="0">
      <failure message="Error: expected 200 &quot;OK&quot;, got 404 &quot;Not Found&quot;
    at Test.Object.&lt;anonymous&gt;.Test._assertStatus (D:\gitworkspace\angular\wings2\angular-node-teamtracker\nodejs\node_modules\supertest\lib\test.js:270:12)
    at Test.Object.&lt;anonymous&gt;.Test._assertFunction (D:\gitworkspace\angular\wings2\angular-node-teamtracker\nodejs\node_modules\supertest\lib\test.js:285:11)
    at Test.Object.&lt;anonymous&gt;.Test.assert (D:\gitworkspace\angular\wings2\angular-node-teamtracker\nodejs\node_modules\supertest\lib\test.js:175:21)
    at Server.localAssert (D:\gitworkspace\angular\wings2\angular-node-teamtracker\nodejs\node_modules\supertest\lib\test.js:133:12)
    at Object.onceWrapper (events.js:519:28)
    at Server.emit (events.js:400:28)
    at emitCloseNT (net.js:1677:8)
    at processTicksAndRejections (internal/process/task_queues.js:81:21)" type="AssertionError">
      </failure>
    </testcase>
    <testcase classname="Adding a new technology to the dropdown" name="Adding a new technology to the dropdown" time="0">
      <failure message="Error: expected 201 &quot;Created&quot;, got 404 &quot;Not Found&quot;
    at Test.Object.&lt;anonymous&gt;.Test._assertStatus (D:\gitworkspace\angular\wings2\angular-node-teamtracker\nodejs\node_modules\supertest\lib\test.js:270:12)
    at Test.Object.&lt;anonymous&gt;.Test._assertFunction (D:\gitworkspace\angular\wings2\angular-node-teamtracker\nodejs\node_modules\supertest\lib\test.js:285:11)
    at Test.Object.&lt;anonymous&gt;.Test.assert (D:\gitworkspace\angular\wings2\angular-node-teamtracker\nodejs\node_modules\supertest\lib\test.js:175:21)
    at Server.localAssert (D:\gitworkspace\angular\wings2\angular-node-teamtracker\nodejs\node_modules\supertest\lib\test.js:133:12)
    at Object.onceWrapper (events.js:519:28)
    at Server.emit (events.js:400:28)
    at emitCloseNT (net.js:1677:8)
    at processTicksAndRejections (internal/process/task_queues.js:81:21)" type="AssertionError">
      </failure>
    </testcase>
    <testcase classname="Adding a new technology to the dropdown" name="Adding a new technology to the dropdown" time="0">
      <failure message="Error: expected 400 &quot;Bad Request&quot;, got 404 &quot;Not Found&quot;
    at Test.Object.&lt;anonymous&gt;.Test._assertStatus (D:\gitworkspace\angular\wings2\angular-node-teamtracker\nodejs\node_modules\supertest\lib\test.js:270:12)
    at Test.Object.&lt;anonymous&gt;.Test._assertFunction (D:\gitworkspace\angular\wings2\angular-node-teamtracker\nodejs\node_modules\supertest\lib\test.js:285:11)
    at Test.Object.&lt;anonymous&gt;.Test.assert (D:\gitworkspace\angular\wings2\angular-node-teamtracker\nodejs\node_modules\supertest\lib\test.js:175:21)
    at Server.localAssert (D:\gitworkspace\angular\wings2\angular-node-teamtracker\nodejs\node_modules\supertest\lib\test.js:133:12)
    at Object.onceWrapper (events.js:519:28)
    at Server.emit (events.js:400:28)
    at emitCloseNT (net.js:1677:8)
    at processTicksAndRejections (internal/process/task_queues.js:81:21)" type="AssertionError">
      </failure>
    </testcase>
    <testcase classname="Removing a new technology to the dropdown" name="Removing a new technology to the dropdown" time="0">
      <failure message="Error: expected 200 &quot;OK&quot;, got 404 &quot;Not Found&quot;
    at Test.Object.&lt;anonymous&gt;.Test._assertStatus (D:\gitworkspace\angular\wings2\angular-node-teamtracker\nodejs\node_modules\supertest\lib\test.js:270:12)
    at Test.Object.&lt;anonymous&gt;.Test._assertFunction (D:\gitworkspace\angular\wings2\angular-node-teamtracker\nodejs\node_modules\supertest\lib\test.js:285:11)
    at Test.Object.&lt;anonymous&gt;.Test.assert (D:\gitworkspace\angular\wings2\angular-node-teamtracker\nodejs\node_modules\supertest\lib\test.js:175:21)
    at Server.localAssert (D:\gitworkspace\angular\wings2\angular-node-teamtracker\nodejs\node_modules\supertest\lib\test.js:133:12)
    at Object.onceWrapper (events.js:519:28)
    at Server.emit (events.js:400:28)
    at emitCloseNT (net.js:1677:8)
    at processTicksAndRejections (internal/process/task_queues.js:81:21)" type="AssertionError">
      </failure>
    </testcase>
    <testcase classname="Getting members from DB" name="Getting members from DB" time="0">
      <failure message="Error: expected 200 &quot;OK&quot;, got 404 &quot;Not Found&quot;
    at Test.Object.&lt;anonymous&gt;.Test._assertStatus (D:\gitworkspace\angular\wings2\angular-node-teamtracker\nodejs\node_modules\supertest\lib\test.js:270:12)
    at Test.Object.&lt;anonymous&gt;.Test._assertFunction (D:\gitworkspace\angular\wings2\angular-node-teamtracker\nodejs\node_modules\supertest\lib\test.js:285:11)
    at Test.Object.&lt;anonymous&gt;.Test.assert (D:\gitworkspace\angular\wings2\angular-node-teamtracker\nodejs\node_modules\supertest\lib\test.js:175:21)
    at Server.localAssert (D:\gitworkspace\angular\wings2\angular-node-teamtracker\nodejs\node_modules\supertest\lib\test.js:133:12)
    at Object.onceWrapper (events.js:519:28)
    at Server.emit (events.js:400:28)
    at emitCloseNT (net.js:1677:8)
    at processTicksAndRejections (internal/process/task_queues.js:81:21)" type="AssertionError">
      </failure>
    </testcase>
    <system-out/>
    <system-err/>
  </testsuite>
</testsuites>